2025-06-18 20:00:16,805 INFO    Thread-2  :19962 [wandb_setup.py:_flush():81] Current SDK version is 0.20.1
2025-06-18 20:00:16,805 INFO    Thread-2  :19962 [wandb_setup.py:_flush():81] Configure stats pid to 19962
2025-06-18 20:00:16,806 INFO    Thread-2  :19962 [wandb_setup.py:_flush():81] Loading settings from /home/fatemehhsaleh/.config/wandb/settings
2025-06-18 20:00:16,806 INFO    Thread-2  :19962 [wandb_setup.py:_flush():81] Loading settings from /home/fatemehhsaleh/RL-PoliTO-MLDL-Project/wandb/settings
2025-06-18 20:00:16,806 INFO    Thread-2  :19962 [wandb_setup.py:_flush():81] Loading settings from environment variables
2025-06-18 20:00:16,807 INFO    Thread-2  :19962 [wandb_init.py:setup_run_log_directory():703] Logging user logs to /home/fatemehhsaleh/RL-PoliTO-MLDL-Project/wandb/run-20250618_200016-ucdp4g5q/logs/debug.log
2025-06-18 20:00:16,807 INFO    Thread-2  :19962 [wandb_init.py:setup_run_log_directory():704] Logging internal logs to /home/fatemehhsaleh/RL-PoliTO-MLDL-Project/wandb/run-20250618_200016-ucdp4g5q/logs/debug-internal.log
2025-06-18 20:00:16,808 INFO    Thread-2  :19962 [wandb_init.py:init():831] calling init triggers
2025-06-18 20:00:16,809 INFO    Thread-2  :19962 [wandb_init.py:init():836] wandb.init called with sweep_config: {'clip_range': 0.2673526086911022, 'entropy_coefficient': 0.014269072213458772, 'learning_rate': 0.0009419377057245196}
config: {'_wandb': {}}
2025-06-18 20:00:16,809 INFO    Thread-2  :19962 [wandb_init.py:init():872] starting backend
2025-06-18 20:00:17,256 INFO    Thread-2  :19962 [wandb_init.py:init():875] sending inform_init request
2025-06-18 20:00:17,327 INFO    Thread-2  :19962 [wandb_init.py:init():883] backend started and connected
2025-06-18 20:00:17,328 INFO    Thread-2  :19962 [wandb_run.py:_config_callback():1358] config_cb None None {'clip_range': 0.2673526086911022, 'entropy_coefficient': 0.014269072213458772, 'learning_rate': 0.0009419377057245196}
2025-06-18 20:00:17,329 INFO    Thread-2  :19962 [wandb_init.py:init():956] updated telemetry
2025-06-18 20:00:17,352 INFO    Thread-2  :19962 [wandb_init.py:init():980] communicating run to backend with 90.0 second timeout
2025-06-18 20:00:19,214 INFO    Thread-2  :19962 [wandb_init.py:init():1032] starting run threads in backend
2025-06-18 20:00:19,438 INFO    Thread-2  :19962 [wandb_run.py:_console_start():2453] atexit reg
2025-06-18 20:00:19,438 INFO    Thread-2  :19962 [wandb_run.py:_redirect():2301] redirect: wrap_raw
2025-06-18 20:00:19,439 INFO    Thread-2  :19962 [wandb_run.py:_redirect():2370] Wrapping output streams.
2025-06-18 20:00:19,440 INFO    Thread-2  :19962 [wandb_run.py:_redirect():2393] Redirects installed.
2025-06-18 20:00:19,443 INFO    Thread-2  :19962 [wandb_init.py:init():1078] run started, returning control to user process
2025-06-18 20:35:25,378 INFO    Thread-1  :19962 [retry.py:__call__():173] [no run ID] Retry attempt failed:
Traceback (most recent call last):
  File "/home/fatemehhsaleh/miniconda3/envs/hopper38/lib/python3.8/site-packages/urllib3/connection.py", line 199, in _new_conn
    sock = connection.create_connection(
  File "/home/fatemehhsaleh/miniconda3/envs/hopper38/lib/python3.8/site-packages/urllib3/util/connection.py", line 60, in create_connection
    for res in socket.getaddrinfo(host, port, family, socket.SOCK_STREAM):
  File "/home/fatemehhsaleh/miniconda3/envs/hopper38/lib/python3.8/socket.py", line 930, in getaddrinfo
    for res in _socket.getaddrinfo(host, port, family, type, proto, flags):
socket.gaierror: [Errno -3] Temporary failure in name resolution

The above exception was the direct cause of the following exception:

Traceback (most recent call last):
  File "/home/fatemehhsaleh/miniconda3/envs/hopper38/lib/python3.8/site-packages/urllib3/connectionpool.py", line 789, in urlopen
    response = self._make_request(
  File "/home/fatemehhsaleh/miniconda3/envs/hopper38/lib/python3.8/site-packages/urllib3/connectionpool.py", line 490, in _make_request
    raise new_e
  File "/home/fatemehhsaleh/miniconda3/envs/hopper38/lib/python3.8/site-packages/urllib3/connectionpool.py", line 466, in _make_request
    self._validate_conn(conn)
  File "/home/fatemehhsaleh/miniconda3/envs/hopper38/lib/python3.8/site-packages/urllib3/connectionpool.py", line 1095, in _validate_conn
    conn.connect()
  File "/home/fatemehhsaleh/miniconda3/envs/hopper38/lib/python3.8/site-packages/urllib3/connection.py", line 693, in connect
    self.sock = sock = self._new_conn()
  File "/home/fatemehhsaleh/miniconda3/envs/hopper38/lib/python3.8/site-packages/urllib3/connection.py", line 206, in _new_conn
    raise NameResolutionError(self.host, self, e) from e
urllib3.exceptions.NameResolutionError: <urllib3.connection.HTTPSConnection object at 0x708b2e9e38b0>: Failed to resolve 'api.wandb.ai' ([Errno -3] Temporary failure in name resolution)

The above exception was the direct cause of the following exception:

Traceback (most recent call last):
  File "/home/fatemehhsaleh/miniconda3/envs/hopper38/lib/python3.8/site-packages/requests/adapters.py", line 667, in send
    resp = conn.urlopen(
  File "/home/fatemehhsaleh/miniconda3/envs/hopper38/lib/python3.8/site-packages/urllib3/connectionpool.py", line 843, in urlopen
    retries = retries.increment(
  File "/home/fatemehhsaleh/miniconda3/envs/hopper38/lib/python3.8/site-packages/urllib3/util/retry.py", line 519, in increment
    raise MaxRetryError(_pool, url, reason) from reason  # type: ignore[arg-type]
urllib3.exceptions.MaxRetryError: HTTPSConnectionPool(host='api.wandb.ai', port=443): Max retries exceeded with url: /graphql (Caused by NameResolutionError("<urllib3.connection.HTTPSConnection object at 0x708b2e9e38b0>: Failed to resolve 'api.wandb.ai' ([Errno -3] Temporary failure in name resolution)"))

During handling of the above exception, another exception occurred:

Traceback (most recent call last):
  File "/home/fatemehhsaleh/miniconda3/envs/hopper38/lib/python3.8/site-packages/wandb/sdk/lib/retry.py", line 134, in __call__
    result = self._call_fn(*args, **kwargs)
  File "/home/fatemehhsaleh/miniconda3/envs/hopper38/lib/python3.8/site-packages/wandb/sdk/internal/internal_api.py", line 396, in execute
    return self.client.execute(*args, **kwargs)  # type: ignore
  File "/home/fatemehhsaleh/miniconda3/envs/hopper38/lib/python3.8/site-packages/wandb/vendor/gql-0.2.0/wandb_gql/client.py", line 52, in execute
    result = self._get_result(document, *args, **kwargs)
  File "/home/fatemehhsaleh/miniconda3/envs/hopper38/lib/python3.8/site-packages/wandb/vendor/gql-0.2.0/wandb_gql/client.py", line 60, in _get_result
    return self.transport.execute(document, *args, **kwargs)
  File "/home/fatemehhsaleh/miniconda3/envs/hopper38/lib/python3.8/site-packages/wandb/sdk/lib/gql_request.py", line 58, in execute
    request = self.session.post(self.url, **post_args)
  File "/home/fatemehhsaleh/miniconda3/envs/hopper38/lib/python3.8/site-packages/requests/sessions.py", line 637, in post
    return self.request("POST", url, data=data, json=json, **kwargs)
  File "/home/fatemehhsaleh/miniconda3/envs/hopper38/lib/python3.8/site-packages/requests/sessions.py", line 589, in request
    resp = self.send(prep, **send_kwargs)
  File "/home/fatemehhsaleh/miniconda3/envs/hopper38/lib/python3.8/site-packages/requests/sessions.py", line 703, in send
    r = adapter.send(request, **kwargs)
  File "/home/fatemehhsaleh/miniconda3/envs/hopper38/lib/python3.8/site-packages/requests/adapters.py", line 700, in send
    raise ConnectionError(e, request=request)
requests.exceptions.ConnectionError: HTTPSConnectionPool(host='api.wandb.ai', port=443): Max retries exceeded with url: /graphql (Caused by NameResolutionError("<urllib3.connection.HTTPSConnection object at 0x708b2e9e38b0>: Failed to resolve 'api.wandb.ai' ([Errno -3] Temporary failure in name resolution)"))
2025-06-18 21:13:41,133 INFO    Thread-1  :19962 [retry.py:__call__():173] [no run ID] Retry attempt failed:
Traceback (most recent call last):
  File "/home/fatemehhsaleh/miniconda3/envs/hopper38/lib/python3.8/site-packages/urllib3/connection.py", line 199, in _new_conn
    sock = connection.create_connection(
  File "/home/fatemehhsaleh/miniconda3/envs/hopper38/lib/python3.8/site-packages/urllib3/util/connection.py", line 60, in create_connection
    for res in socket.getaddrinfo(host, port, family, socket.SOCK_STREAM):
  File "/home/fatemehhsaleh/miniconda3/envs/hopper38/lib/python3.8/socket.py", line 930, in getaddrinfo
    for res in _socket.getaddrinfo(host, port, family, type, proto, flags):
socket.gaierror: [Errno -3] Temporary failure in name resolution

The above exception was the direct cause of the following exception:

Traceback (most recent call last):
  File "/home/fatemehhsaleh/miniconda3/envs/hopper38/lib/python3.8/site-packages/urllib3/connectionpool.py", line 789, in urlopen
    response = self._make_request(
  File "/home/fatemehhsaleh/miniconda3/envs/hopper38/lib/python3.8/site-packages/urllib3/connectionpool.py", line 490, in _make_request
    raise new_e
  File "/home/fatemehhsaleh/miniconda3/envs/hopper38/lib/python3.8/site-packages/urllib3/connectionpool.py", line 466, in _make_request
    self._validate_conn(conn)
  File "/home/fatemehhsaleh/miniconda3/envs/hopper38/lib/python3.8/site-packages/urllib3/connectionpool.py", line 1095, in _validate_conn
    conn.connect()
  File "/home/fatemehhsaleh/miniconda3/envs/hopper38/lib/python3.8/site-packages/urllib3/connection.py", line 693, in connect
    self.sock = sock = self._new_conn()
  File "/home/fatemehhsaleh/miniconda3/envs/hopper38/lib/python3.8/site-packages/urllib3/connection.py", line 206, in _new_conn
    raise NameResolutionError(self.host, self, e) from e
urllib3.exceptions.NameResolutionError: <urllib3.connection.HTTPSConnection object at 0x708b2e9e33a0>: Failed to resolve 'api.wandb.ai' ([Errno -3] Temporary failure in name resolution)

The above exception was the direct cause of the following exception:

Traceback (most recent call last):
  File "/home/fatemehhsaleh/miniconda3/envs/hopper38/lib/python3.8/site-packages/requests/adapters.py", line 667, in send
    resp = conn.urlopen(
  File "/home/fatemehhsaleh/miniconda3/envs/hopper38/lib/python3.8/site-packages/urllib3/connectionpool.py", line 843, in urlopen
    retries = retries.increment(
  File "/home/fatemehhsaleh/miniconda3/envs/hopper38/lib/python3.8/site-packages/urllib3/util/retry.py", line 519, in increment
    raise MaxRetryError(_pool, url, reason) from reason  # type: ignore[arg-type]
urllib3.exceptions.MaxRetryError: HTTPSConnectionPool(host='api.wandb.ai', port=443): Max retries exceeded with url: /graphql (Caused by NameResolutionError("<urllib3.connection.HTTPSConnection object at 0x708b2e9e33a0>: Failed to resolve 'api.wandb.ai' ([Errno -3] Temporary failure in name resolution)"))

During handling of the above exception, another exception occurred:

Traceback (most recent call last):
  File "/home/fatemehhsaleh/miniconda3/envs/hopper38/lib/python3.8/site-packages/wandb/sdk/lib/retry.py", line 134, in __call__
    result = self._call_fn(*args, **kwargs)
  File "/home/fatemehhsaleh/miniconda3/envs/hopper38/lib/python3.8/site-packages/wandb/sdk/internal/internal_api.py", line 396, in execute
    return self.client.execute(*args, **kwargs)  # type: ignore
  File "/home/fatemehhsaleh/miniconda3/envs/hopper38/lib/python3.8/site-packages/wandb/vendor/gql-0.2.0/wandb_gql/client.py", line 52, in execute
    result = self._get_result(document, *args, **kwargs)
  File "/home/fatemehhsaleh/miniconda3/envs/hopper38/lib/python3.8/site-packages/wandb/vendor/gql-0.2.0/wandb_gql/client.py", line 60, in _get_result
    return self.transport.execute(document, *args, **kwargs)
  File "/home/fatemehhsaleh/miniconda3/envs/hopper38/lib/python3.8/site-packages/wandb/sdk/lib/gql_request.py", line 58, in execute
    request = self.session.post(self.url, **post_args)
  File "/home/fatemehhsaleh/miniconda3/envs/hopper38/lib/python3.8/site-packages/requests/sessions.py", line 637, in post
    return self.request("POST", url, data=data, json=json, **kwargs)
  File "/home/fatemehhsaleh/miniconda3/envs/hopper38/lib/python3.8/site-packages/requests/sessions.py", line 589, in request
    resp = self.send(prep, **send_kwargs)
  File "/home/fatemehhsaleh/miniconda3/envs/hopper38/lib/python3.8/site-packages/requests/sessions.py", line 703, in send
    r = adapter.send(request, **kwargs)
  File "/home/fatemehhsaleh/miniconda3/envs/hopper38/lib/python3.8/site-packages/requests/adapters.py", line 700, in send
    raise ConnectionError(e, request=request)
requests.exceptions.ConnectionError: HTTPSConnectionPool(host='api.wandb.ai', port=443): Max retries exceeded with url: /graphql (Caused by NameResolutionError("<urllib3.connection.HTTPSConnection object at 0x708b2e9e33a0>: Failed to resolve 'api.wandb.ai' ([Errno -3] Temporary failure in name resolution)"))
2025-06-18 23:02:16,403 INFO    Thread-2  :19962 [wandb_run.py:_finish():2219] finishing run fatemehhsaleh-politecnico-di-torino/F_MldlRLproject_TuningPPO_Source_Target/ucdp4g5q
2025-06-18 23:02:16,405 INFO    Thread-2  :19962 [wandb_run.py:_atexit_cleanup():2418] got exitcode: 0
2025-06-18 23:02:16,405 INFO    Thread-2  :19962 [wandb_run.py:_restore():2400] restore
2025-06-18 23:02:16,405 INFO    Thread-2  :19962 [wandb_run.py:_restore():2406] restore done
2025-06-18 23:30:30,977 INFO    Thread-2  :19962 [wandb_run.py:_footer_history_summary_info():4000] rendering history
2025-06-18 23:30:30,979 INFO    Thread-2  :19962 [wandb_run.py:_footer_history_summary_info():4032] rendering summary
2025-06-18 23:30:30,981 INFO    Thread-2  :19962 [wandb_run.py:_footer_sync_info():3961] logging synced files
