2025-06-22 00:09:10,970 INFO    Thread-31 :579038 [wandb_setup.py:_flush():81] Current SDK version is 0.20.1
2025-06-22 00:09:10,970 INFO    Thread-31 :579038 [wandb_setup.py:_flush():81] Configure stats pid to 579038
2025-06-22 00:09:10,970 INFO    Thread-31 :579038 [wandb_setup.py:_flush():81] Loading settings from /root/.config/wandb/settings
2025-06-22 00:09:10,970 INFO    Thread-31 :579038 [wandb_setup.py:_flush():81] Loading settings from /app/wandb/settings
2025-06-22 00:09:10,970 INFO    Thread-31 :579038 [wandb_setup.py:_flush():81] Loading settings from environment variables
2025-06-22 00:09:10,970 INFO    Thread-31 :579038 [wandb_init.py:setup_run_log_directory():703] Logging user logs to /app/wandb/run-20250622_000910-8fn8st2g/logs/debug.log
2025-06-22 00:09:10,970 INFO    Thread-31 :579038 [wandb_init.py:setup_run_log_directory():704] Logging internal logs to /app/wandb/run-20250622_000910-8fn8st2g/logs/debug-internal.log
2025-06-22 00:09:10,971 INFO    Thread-31 :579038 [wandb_init.py:init():831] calling init triggers
2025-06-22 00:09:10,971 INFO    Thread-31 :579038 [wandb_init.py:init():836] wandb.init called with sweep_config: {'batch_size': 128, 'clip_range': 0.29960550952813453, 'entropy_coefficient': 0.016184463676716193, 'gae_lambda': 0.9748081993629228, 'gamma': 0.9764819449091392, 'learning_rate': 0.0006725495202063207, 'n_steps': 2048}
config: {'_wandb': {}}
2025-06-22 00:09:10,971 INFO    Thread-31 :579038 [wandb_init.py:init():872] starting backend
2025-06-22 00:09:11,192 INFO    Thread-31 :579038 [wandb_init.py:init():875] sending inform_init request
2025-06-22 00:09:11,199 INFO    Thread-31 :579038 [wandb_init.py:init():883] backend started and connected
2025-06-22 00:09:11,203 INFO    Thread-31 :579038 [wandb_run.py:_config_callback():1358] config_cb None None {'batch_size': 128, 'clip_range': 0.29960550952813453, 'entropy_coefficient': 0.016184463676716193, 'gae_lambda': 0.9748081993629228, 'gamma': 0.9764819449091392, 'learning_rate': 0.0006725495202063207, 'n_steps': 2048}
2025-06-22 00:09:11,220 INFO    Thread-31 :579038 [wandb_init.py:init():956] updated telemetry
2025-06-22 00:09:11,232 INFO    Thread-31 :579038 [wandb_init.py:init():980] communicating run to backend with 90.0 second timeout
2025-06-22 00:09:11,894 INFO    Thread-31 :579038 [wandb_init.py:init():1032] starting run threads in backend
2025-06-22 00:09:11,988 INFO    Thread-31 :579038 [wandb_run.py:_console_start():2453] atexit reg
2025-06-22 00:09:11,988 INFO    Thread-31 :579038 [wandb_run.py:_redirect():2301] redirect: wrap_raw
2025-06-22 00:09:11,988 INFO    Thread-31 :579038 [wandb_run.py:_redirect():2370] Wrapping output streams.
2025-06-22 00:09:11,989 INFO    Thread-31 :579038 [wandb_run.py:_redirect():2393] Redirects installed.
2025-06-22 00:09:11,989 INFO    Thread-31 :579038 [wandb_init.py:init():1078] run started, returning control to user process
2025-06-22 01:02:54,173 INFO    Thread-1  :579038 [retry.py:__call__():173] [no run ID] Retry attempt failed:
Traceback (most recent call last):
  File "/usr/local/lib/python3.9/dist-packages/urllib3/connection.py", line 174, in _new_conn
    conn = connection.create_connection(
  File "/usr/local/lib/python3.9/dist-packages/urllib3/util/connection.py", line 72, in create_connection
    for res in socket.getaddrinfo(host, port, family, socket.SOCK_STREAM):
  File "/usr/lib/python3.9/socket.py", line 953, in getaddrinfo
    for res in _socket.getaddrinfo(host, port, family, type, proto, flags):
socket.gaierror: [Errno -2] Name or service not known

During handling of the above exception, another exception occurred:

Traceback (most recent call last):
  File "/usr/local/lib/python3.9/dist-packages/urllib3/connectionpool.py", line 703, in urlopen
    httplib_response = self._make_request(
  File "/usr/local/lib/python3.9/dist-packages/urllib3/connectionpool.py", line 386, in _make_request
    self._validate_conn(conn)
  File "/usr/local/lib/python3.9/dist-packages/urllib3/connectionpool.py", line 1042, in _validate_conn
    conn.connect()
  File "/usr/local/lib/python3.9/dist-packages/urllib3/connection.py", line 358, in connect
    self.sock = conn = self._new_conn()
  File "/usr/local/lib/python3.9/dist-packages/urllib3/connection.py", line 186, in _new_conn
    raise NewConnectionError(
urllib3.exceptions.NewConnectionError: <urllib3.connection.HTTPSConnection object at 0x7fde1461d700>: Failed to establish a new connection: [Errno -2] Name or service not known

During handling of the above exception, another exception occurred:

Traceback (most recent call last):
  File "/usr/local/lib/python3.9/dist-packages/requests/adapters.py", line 489, in send
    resp = conn.urlopen(
  File "/usr/local/lib/python3.9/dist-packages/urllib3/connectionpool.py", line 787, in urlopen
    retries = retries.increment(
  File "/usr/local/lib/python3.9/dist-packages/urllib3/util/retry.py", line 592, in increment
    raise MaxRetryError(_pool, url, error or ResponseError(cause))
urllib3.exceptions.MaxRetryError: HTTPSConnectionPool(host='api.wandb.ai', port=443): Max retries exceeded with url: /graphql (Caused by NewConnectionError('<urllib3.connection.HTTPSConnection object at 0x7fde1461d700>: Failed to establish a new connection: [Errno -2] Name or service not known'))

During handling of the above exception, another exception occurred:

Traceback (most recent call last):
  File "/usr/local/lib/python3.9/dist-packages/wandb/sdk/lib/retry.py", line 134, in __call__
    result = self._call_fn(*args, **kwargs)
  File "/usr/local/lib/python3.9/dist-packages/wandb/sdk/internal/internal_api.py", line 396, in execute
    return self.client.execute(*args, **kwargs)  # type: ignore
  File "/usr/local/lib/python3.9/dist-packages/wandb/vendor/gql-0.2.0/wandb_gql/client.py", line 52, in execute
    result = self._get_result(document, *args, **kwargs)
  File "/usr/local/lib/python3.9/dist-packages/wandb/vendor/gql-0.2.0/wandb_gql/client.py", line 60, in _get_result
    return self.transport.execute(document, *args, **kwargs)
  File "/usr/local/lib/python3.9/dist-packages/wandb/sdk/lib/gql_request.py", line 58, in execute
    request = self.session.post(self.url, **post_args)
  File "/usr/local/lib/python3.9/dist-packages/requests/sessions.py", line 635, in post
    return self.request("POST", url, data=data, json=json, **kwargs)
  File "/usr/local/lib/python3.9/dist-packages/requests/sessions.py", line 587, in request
    resp = self.send(prep, **send_kwargs)
  File "/usr/local/lib/python3.9/dist-packages/requests/sessions.py", line 701, in send
    r = adapter.send(request, **kwargs)
  File "/usr/local/lib/python3.9/dist-packages/requests/adapters.py", line 565, in send
    raise ConnectionError(e, request=request)
requests.exceptions.ConnectionError: HTTPSConnectionPool(host='api.wandb.ai', port=443): Max retries exceeded with url: /graphql (Caused by NewConnectionError('<urllib3.connection.HTTPSConnection object at 0x7fde1461d700>: Failed to establish a new connection: [Errno -2] Name or service not known'))
2025-06-22 01:59:39,685 INFO    Thread-31 :579038 [wandb_run.py:_finish():2219] finishing run hossein-ahmadzadeh-politecnico-di-torino/RL-Hopper-PPO-Tuning/8fn8st2g
2025-06-22 01:59:39,685 INFO    Thread-31 :579038 [wandb_run.py:_atexit_cleanup():2418] got exitcode: 0
2025-06-22 01:59:39,686 INFO    Thread-31 :579038 [wandb_run.py:_restore():2400] restore
2025-06-22 01:59:39,686 INFO    Thread-31 :579038 [wandb_run.py:_restore():2406] restore done
2025-06-22 01:59:40,810 INFO    Thread-31 :579038 [wandb_run.py:_footer_history_summary_info():4000] rendering history
2025-06-22 01:59:40,813 INFO    Thread-31 :579038 [wandb_run.py:_footer_history_summary_info():4032] rendering summary
2025-06-22 01:59:40,815 INFO    Thread-31 :579038 [wandb_run.py:_footer_sync_info():3961] logging synced files
